Workbook

Sheet Instructions
A1: Finance Function Digitalisation Roadmap
A2: A 12-month digitalisation roadmap planning tool for finance functions — current state assessment, priority initiative framework, resource requirement planner, and KPI dashboard.
A4: How This Workbook Is Organised
A5: – Current State Assessment: Score your finance function's digital maturity across 5 dimensions to establish your starting point.
A6: – Priority Initiative Framework: Score candidate initiatives by impact and effort to decide what to tackle first.
A7: – 12-Month Roadmap: A dynamic Gantt view — set a start month and duration per initiative and the timeline shades itself in.
A8: – Resource Requirement Planner: Budget, internal hours, and vendor costs per initiative, with a rolled-up total.
A9: – KPI Dashboard: Baseline, target, and current values for 8 measures that track whether the roadmap is actually working.
A11: Colour Legend
A12: – Blue text = an input cell you should fill in or edit for your own organisation.
A13: – Black text = a formula — do not overtype, or the roadmap will stop calculating correctly.
A14: – Green text = a link pulling data from another tab.
... A27: A roadmap is a planning tool, not a contract. Revisit the Priority Framework and Roadmap tabs at least quarterly as priorities and constraints shift.

Sheet Current State Assessment
A1: Current State Assessment
A2: Score each statement 1 (Rarely/Never) to 5 (Consistently/Fully) as a team, not just from one perspective.
A4: Core Systems & ERP
A5: Statement | C5: Score (1-5)
A6: Our core financial system is a single, integrated platform rather than a patchwork of disconnected tools. | C6: 3
A7: We can access accurate financial data in real time, not just after a manual export or reconciliation. | C7: 3
A8: Adding a new entity, cost centre, or reporting need doesn't require significant manual system rework. | C8: 3
A9: Our system vendor actively supports us with updates, security patches, and a credible product roadmap. | C9: 3
A10: Core Systems & ERP — Dimension Score | C10: =SUM(C6:C9) -> 12 | D10: / 20
A12: Data & Reporting
A13: Statement | C13: Score (1-5)
A14: Standard management reports are generated automatically, not rebuilt manually each period. | C14: 3
A15: Stakeholders can self-serve common reporting needs without submitting a request to finance. | C15: 3
A16: We trust our data enough to act on a dashboard number without re-verifying it manually first. | C16: 3
A17: Report definitions (what a metric means) are documented and consistent across the organisation. | C17: 3
A18: Data & Reporting — Dimension Score | C18: =SUM(C14:C17) -> 12 | D18: / 20
A20: Process Automation
A21: Statement | C21: Score (1-5)
A22: Routine reconciliations (bank, AR, AP) are substantially automated, not manually matched line by line. | C22: 3
A23: Month-end close relies on defined, largely automated workflows rather than ad hoc effort each period. | C23: 3
A24: Repetitive, high-volume tasks (data entry, standard journal entries) are automated or assisted by tools. | C24: 3
A25: We have actively evaluated AI or RPA tools for at least one real finance process, not just discussed it. | C25: 3
A26: Process Automation — Dimension Score | C26: =SUM(C22:C25) -> 12 | D26: / 20
A28: Team Skills & Capability
A29: Statement | C29: Score (1-5)
A30: Our finance team is comfortable using the digital tools already available to them, not just tolerating them. | C30: 3
A31: At least one person on the team can build or maintain intermediate automation (Power Query, macros, scripts). | C31: 3
A32: The team receives some ongoing training on new digital tools, not just onboarding training once. | C32: 3
A33: The team sees digitalisation as making their work better, not primarily as a threat to their role. | C33: 3
A34: Team Skills & Capability — Dimension Score | C34: =SUM(C30:C33) -> 12 | D34: / 20
A36: Governance & Controls
A37: Statement | C37: Score (1-5)
A38: We have a clear view of who has access to which financial systems and data, and it's reviewed periodically. | C38: 3
A39: Controls have been explicitly reviewed and updated for the automated processes we've already implemented. | C39: 3
A40: There is a named owner responsible for data governance and AI/tool usage decisions in finance. | C40: 3
A41: We have a clear process for evaluating a new digital tool before it touches real financial data. | C41: 3
A42: Governance & Controls — Dimension Score | C42: =SUM(C38:C41) -> 12 | D42: / 20
A44: OVERALL DIGITAL MATURITY SCORE
A45: Core Systems & ERP | C45: =C10 -> 12 | D45: / 20
A46: Data & Reporting | C46: =C18 -> 12 | D46: / 20
...

Sheet Priority Initiative Framework
A1: Priority Initiative Framework
A2: Score each candidate initiative on Impact (1-5) and Effort (1-5). Priority Score and Tier calculate automatically — replace or add initiative rows to fit your own organisation.
A4: Initiative | B4: Impact (1-5) | C4: Effort (1-5) | D4: Priority Score | E4: Priority Tier | F4: Notes
A5: Automate bank & cash reconciliation | B5: 4 | C5: 2 | D5: =B5*2-C5 -> 6 | E5: =IF(AND(B5>=4,C5<=2),"Quick Win",IF(AND(B5>=4,C5>=3),"Major Project",IF(AND(B5<=3,C5<=2),"Fill-In","Deprioritise"))) -> Quick Win | F5: Strong quick-win candidate — mature tools, low disruption.
A6: AI-assisted month-end close checklist & workflow | B6: 4 | C6: 3 | D6: =B6*2-C6 -> 5 | E6: =IF(AND(B6>=4,C6<=2),"Quick Win",IF(AND(B6>=4,C6>=3),"Major Project",IF(AND(B6<=3,C6<=2),"Fill-In","Deprioritise"))) -> Major Project | F6: Builds on existing close process rather than replacing it.
A7: Deploy Copilot / AI tools in Excel for reporting | B7: 3 | C7: 2 | D7: =B7*2-C7 -> 4 | E7: =IF(AND(B7>=4,C7<=2),"Quick Win",IF(AND(B7>=4,C7>=3),"Major Project",IF(AND(B7<=3,C7<=2),"Fill-In","Deprioritise"))) -> Fill-In | F7: Low-cost pilot; licensing already in place for many teams.
A8: Rolling 13-week cash flow forecasting model | B8: 4 | C8: 2 | D8: =B8*2-C8 -> 6 | E8: =IF(AND(B8>=4,C8<=2),"Quick Win",IF(AND(B8>=4,C8>=3),"Major Project",IF(AND(B8<=3,C8<=2),"Fill-In","Deprioritise"))) -> Quick Win | F8: High visibility win for leadership and lenders.
A9: Automate AP invoice processing (OCR / matching) | B9: 5 | C9: 4 | D9: =B9*2-C9 -> 6 | E9: =IF(AND(B9>=4,C9<=2),"Quick Win",IF(AND(B9>=4,C9>=3),"Major Project",IF(AND(B9<=3,C9<=2),"Fill-In","Deprioritise"))) -> Major Project | F9: High volume, high manual effort today — worth the build cost.
A10: Automate AR collections & dunning workflow | B10: 4 | C10: 3 | D10: =B10*2-C10 -> 5 | E10: =IF(AND(B10>=4,C10<=2),"Quick Win",IF(AND(B10>=4,C10>=3),"Major Project",IF(AND(B10<=3,C10<=2),"Fill-In","Deprioritise"))) -> Major Project | F10: Directly improves cash position, not just efficiency.
A11: RPA for repetitive journal entries | B11: 3 | C11: 3 | D11: =B11*2-C11 -> 3 | E11: =IF(AND(B11>=4,C11<=2),"Quick Win",IF(AND(B11>=4,C11>=3),"Major Project",IF(AND(B11<=3,C11<=2),"Fill-In","Deprioritise"))) -> Deprioritise | F11: Good candidate once close process is documented and stable.
A12: Self-service BI dashboards for stakeholders | B12: 4 | C12: 4 | D12: =B12*2-C12 -> 4 | E12: =IF(AND(B12>=4,C12<=2),"Quick Win",IF(AND(B12>=4,C12>=3),"Major Project",IF(AND(B12<=3,C12<=2),"Fill-In","Deprioritise"))) -> Major Project | F12: Reduces ad hoc reporting requests once adopted.
A13: Migrate to cloud ERP / upgrade core system | B13: 5 | C13: 5 | D13: =B13*2-C13 -> 5 | E13: =IF(AND(B13>=4,C13<=2),"Quick Win",IF(AND(B13>=4,C13>=3),"Major Project",IF(AND(B13<=3,C13<=2),"Fill-In","Deprioritise"))) -> Major Project | F13: Highest impact, highest effort — needs its own project plan.
A14: E-signature & digital approval workflows | B14: 3 | C14: 1 | D14: =B14*2-C14 -> 5 | E14: =IF(AND(B14>=4,C14<=2),"Quick Win",IF(AND(B14>=4,C14>=3),"Major Project",IF(AND(B14<=3,C14<=2),"Fill-In","Deprioritise"))) -> Fill-In | F14: Fast to implement, meaningful control and speed benefit.
A15: Automate variance analysis & flux reporting | B15: 4 | C15: 3 | D15: =B15*2-C15 -> 5 | E15: =IF(AND(B15>=4,C15<=2),"Quick Win",IF(AND(B15>=4,C15>=3),"Major Project",IF(AND(B15<=3,C15<=2),"Fill-In","Deprioritise"))) -> Major Project | F15: Pairs well with the BI dashboard initiative above.
A16: Financial data warehouse / single source of truth | B16: 5 | C16: 5 | D16: =B16*2-C16 -> 5 | E16: =IF(AND(B16>=4,C16<=2),"Quick Win",IF(AND(B16>=4,C16>=3),"Major Project",IF(AND(B16<=3,C16<=2),"Fill-In","Deprioritise"))) -> Major Project | F16: Foundational for everything else — sequence carefully.
... A19: Establish AI / data governance framework | B19: 4 | C19: 2 | D19: =B19*2-C19 -> 6 | E19: =IF(AND(B19>=4,C19<=2),"Quick Win",IF(AND(B19>=4,C19>=3),"Major Project",IF(AND(B19<=3,C19<=2),"Fill-In","Deprioritise"))) -> Quick Win | F19: Do this early — retrofitting governance later is harder.
A21: PRIORITY TIER LOGIC
A22: Quick Win | C22: Impact ≥ 4, Effort ≤ 2 | E22: Do these first — high return, low disruption.
A23: Major Project | C23: Impact ≥ 4, Effort ≥ 3 | E23: Worth doing, but needs proper planning and resourcing.
A24: Fill-In | C24: Impact ≤ 3, Effort ≤ 2 | E24: Nice to have — slot in around higher-priority work.
A25: Deprioritise | C25: Everything else | E25: Low return for the effort required — revisit later if priorities shift.

Sheet 12-Month Roadmap
A1: 12-Month Roadmap
A2: Set a Start Month (1-12) and Duration (months) for each initiative — the timeline shades itself in automatically, colour-coded by Priority Tier from the framework tab.
A4: Initiative | B4: Start Month | C4: Duration (Months) | D4: Priority Tier | E4: M1 | F4: M2 | G4: M3 | H4: M4 | I4: M5 | J4: M6 | K4: M7 | L4: M8 | M4: M9 | N4: M10 | O4: M11 | P4: M12
A5: ='Priority Initiative Framework'!A5 -> Automate bank & cash reconciliation | B5: 1 | C5: 2 | D5: ='Priority Initiative Framework'!E5 -> Quick Win
A6: ='Priority Initiative Framework'!A6 -> AI-assisted month-end close checklist & workflow | B6: 2 | C6: 3 | D6: ='Priority Initiative Framework'!E6 -> Major Project
A7: ='Priority Initiative Framework'!A7 -> Deploy Copilot / AI tools in Excel for reporting | B7: 1 | C7: 2 | D7: ='Priority Initiative Framework'!E7 -> Fill-In
A8: ='Priority Initiative Framework'!A8 -> Rolling 13-week cash flow forecasting model | B8: 3 | C8: 2 | D8: ='Priority Initiative Framework'!E8 -> Quick Win
A9: ='Priority Initiative Framework'!A9 -> Automate AP invoice processing (OCR / matching) | B9: 4 | C9: 4 | D9: ='Priority Initiative Framework'!E9 -> Major Project
A10: ='Priority Initiative Framework'!A10 -> Automate AR collections & dunning workflow | B10: 5 | C10: 3 | D10: ='Priority Initiative Framework'!E10 -> Major Project
A11: ='Priority Initiative Framework'!A11 -> RPA for repetitive journal entries | B11: 6 | C11: 3 | D11: ='Priority Initiative Framework'!E11 -> Deprioritise
A12: ='Priority Initiative Framework'!A12 -> Self-service BI dashboards for stakeholders | B12: 7 | C12: 4 | D12: ='Priority Initiative Framework'!E12 -> Major Project
A13: ='Priority Initiative Framework'!A13 -> Migrate to cloud ERP / upgrade core system | B13: 5 | C13: 8 | D13: ='Priority Initiative Framework'!E13 -> Major Project
A14: ='Priority Initiative Framework'!A14 -> E-signature & digital approval workflows | B14: 2 | C14: 1 | D14: ='Priority Initiative Framework'!E14 -> Fill-In
A15: ='Priority Initiative Framework'!A15 -> Automate variance analysis & flux reporting | B15: 7 | C15: 3 | D15: ='Priority Initiative Framework'!E15 -> Major Project
A16: ='Priority Initiative Framework'!A16 -> Financial data warehouse / single source of truth | B16: 6 | C16: 6 | D16: ='Priority Initiative Framework'!E16 -> Major Project
... A19: ='Priority Initiative Framework'!A19 -> Establish AI / data governance framework | B19: 1 | C19: 2 | D19: ='Priority Initiative Framework'!E19 -> Quick Win
A21: COLOUR KEY (matches Priority Tier from the framework tab)
A22: Quick Win
A23: Major Project
A24: Fill-In
A25: Deprioritise

Sheet Resource Requirement Planner
A1: Resource Requirement Planner
A2: Estimate the internal and external resource each initiative needs. Total Cost and the rollup below calculate automatically.
A4: Initiative | B4: Internal FTE Hours / Week | C4: External / Vendor Cost ($) | D4: Software / Tool Cost ($) | E4: Department(s) Involved | F4: Total Cost ($)
A5: ='Priority Initiative Framework'!A5 -> Automate bank & cash reconciliation | B5: 8 | C5: 3000 | D5: 6000 | E5: Accounting, IT | F5: =C5+D5 -> 9000
A6: ='Priority Initiative Framework'!A6 -> AI-assisted month-end close checklist & workflow | B6: 6 | C6: 5000 | D6: 4000 | E6: Accounting, FP&A | F6: =C6+D6 -> 9000
A7: ='Priority Initiative Framework'!A7 -> Deploy Copilot / AI tools in Excel for reporting | B7: 4 | C7: 0 | D7: 2400 | E7: FP&A, Reporting | F7: =C7+D7 -> 2400
A8: ='Priority Initiative Framework'!A8 -> Rolling 13-week cash flow forecasting model | B8: 6 | C8: 4000 | D8: 3000 | E8: Treasury, FP&A | F8: =C8+D8 -> 7000
A9: ='Priority Initiative Framework'!A9 -> Automate AP invoice processing (OCR / matching) | B9: 10 | C9: 25000 | D9: 15000 | E9: AP, IT, Procurement | F9: =C9+D9 -> 40000
A10: ='Priority Initiative Framework'!A10 -> Automate AR collections & dunning workflow | B10: 8 | C10: 15000 | D10: 8000 | E10: AR, Credit Control | F10: =C10+D10 -> 23000
A11: ='Priority Initiative Framework'!A11 -> RPA for repetitive journal entries | B11: 6 | C11: 8000 | D11: 5000 | E11: Accounting, IT | F11: =C11+D11 -> 13000
A12: ='Priority Initiative Framework'!A12 -> Self-service BI dashboards for stakeholders | B12: 8 | C12: 12000 | D12: 10000 | E12: FP&A, Reporting, IT | F12: =C12+D12 -> 22000
A13: ='Priority Initiative Framework'!A13 -> Migrate to cloud ERP / upgrade core system | B13: 20 | C13: 150000 | D13: 80000 | E13: All Finance, IT | F13: =C13+D13 -> 230000
A14: ='Priority Initiative Framework'!A14 -> E-signature & digital approval workflows | B14: 3 | C14: 2000 | D14: 1500 | E14: Accounting, Legal | F14: =C14+D14 -> 3500
A15: ='Priority Initiative Framework'!A15 -> Automate variance analysis & flux reporting | B15: 5 | C15: 6000 | D15: 4000 | E15: FP&A, Reporting | F15: =C15+D15 -> 10000
A16: ='Priority Initiative Framework'!A16 -> Financial data warehouse / single source of truth | B16: 15 | C16: 60000 | D16: 40000 | E16: All Finance, IT | F16: =C16+D16 -> 100000
... A19: ='Priority Initiative Framework'!A19 -> Establish AI / data governance framework | B19: 3 | C19: 10000 | D19: 2000 | E19: Finance Leadership, IT | F19: =C19+D19 -> 12000
A21: PROGRAMME TOTALS
A22: Total Internal FTE Hours / Week (across all active initiatives) | F22: =SUM(B5:B19) -> 116
A23: Total External / Vendor Cost | F23: =SUM(C5:C19) -> 313000
A24: Total Software / Tool Cost | F24: =SUM(D5:D19) -> 183900
A25: TOTAL PROGRAMME COST | F25: =SUM(F5:F19) -> 496900
A27: Cost by Priority Tier:
A28: Quick Win | F28: =SUMIF('Priority Initiative Framework'!$E$5:$E$19,"Quick Win",F5:F19) -> 36000
A29: Major Project | F29: =SUMIF('Priority Initiative Framework'!$E$5:$E$19,"Major Project",F5:F19) -> 442000
A30: Fill-In | F30: =SUMIF('Priority Initiative Framework'!$E$5:$E$19,"Fill-In",F5:F19) -> 5900
A31: Deprioritise | F31: =SUMIF('Priority Initiative Framework'!$E$5:$E$19,"Deprioritise",F5:F19) -> 13000

Sheet KPI Dashboard
A1: KPI Dashboard
A2: Set Baseline and Target when you start the roadmap. Update Current each month — Status and Progress calculate automatically.
A4: KPI | B4: Direction | C4: Baseline | D4: Target | E4: Current | F4: Progress | G4: Status
A5: % of Month-End Close Tasks Automated | B5: Higher is Better | C5: 0.2 | D5: 0.7 | E5: 0.35 | F5: =IF(B5="Higher is Better",(E5-C5)/(D5-C5),(C5-E5)/(C5-D5)) -> 0.3 | G5: =IF(F5>=1,"Achieved",IF(F5>=0.5,"On Track","Behind")) -> Behind
A6: Days to Close (Calendar Days) | B6: Lower is Better | C6: 10 | D6: 5 | E6: 8 | F6: =IF(B6="Higher is Better",(E6-C6)/(D6-C6),(C6-E6)/(C6-D6)) -> 0.4 | G6: =IF(F6>=1,"Achieved",IF(F6>=0.5,"On Track","Behind")) -> Behind
A7: Manual Journal Entries per Month | B7: Lower is Better | C7: 150 | D7: 40 | E7: 95 | F7: =IF(B7="Higher is Better",(E7-C7)/(D7-C7),(C7-E7)/(C7-D7)) -> 0.5 | G7: =IF(F7>=1,"Achieved",IF(F7>=0.5,"On Track","Behind")) -> On Track
A8: % of Invoices Processed Touchless | B8: Higher is Better | C8: 0.15 | D8: 0.6 | E8: 0.28 | F8: =IF(B8="Higher is Better",(E8-C8)/(D8-C8),(C8-E8)/(C8-D8)) -> 0.28888889 | G8: =IF(F8>=1,"Achieved",IF(F8>=0.5,"On Track","Behind")) -> Behind
A9: Average Report Generation Time (Hours) | B9: Lower is Better | C9: 12 | D9: 2 | E9: 7 | F9: =IF(B9="Higher is Better",(E9-C9)/(D9-C9),(C9-E9)/(C9-D9)) -> 0.5 | G9: =IF(F9>=1,"Achieved",IF(F9>=0.5,"On Track","Behind")) -> On Track
A10: Reconciliation Exceptions per Month | B10: Lower is Better | C10: 45 | D10: 15 | E10: 30 | F10: =IF(B10="Higher is Better",(E10-C10)/(D10-C10),(C10-E10)/(C10-D10)) -> 0.5 | G10: =IF(F10>=1,"Achieved",IF(F10>=0.5,"On Track","Behind")) -> On Track
A11: Finance Team Hours on Manual Data Entry / Week | B11: Lower is Better | C11: 25 | D11: 8 | E11: 16 | F11: =IF(B11="Higher is Better",(E11-C11)/(D11-C11),(C11-E11)/(C11-D11)) -> 0.52941176 | G11: =IF(F11>=1,"Achieved",IF(F11>=0.5,"On Track","Behind")) -> On Track
A12: % of Forecasts Using Live/Automated Data Feeds | B12: Higher is Better | C12: 0.1 | D12: 0.8 | E12: 0.25 | F12: =IF(B12="Higher is Better",(E12-C12)/(D12-C12),(C12-E12)/(C12-D12)) -> 0.21428571 | G12: =IF(F12>=1,"Achieved",IF(F12>=0.5,"On Track","Behind")) -> Behind
A14: SUMMARY
A15: KPIs Achieved: | C15: =COUNTIF(G5:G12,"Achieved") -> 0
A16: KPIs On Track: | C16: =COUNTIF(G5:G12,"On Track") -> 4
A17: KPIs Behind: | C17: =COUNTIF(G5:G12,"Behind") -> 4
